Workbook

Sheet Sheet8
B2: month | C2: coffee | D2: month | E2: coffee | F2: tea | G2: smoothie
B3: Jan | C3: 3700 | D3: Jan | E3: =C3/C$15 -> 0.10070219 | F3: =B18/B$30 -> 0.09528515 | G3: =C18/C$30 -> 0.09765625
B4: Fed | C4: 2920 | D4: Fed | E4: =C4/C$15 -> 0.079473083 | F4: =B19/B$30 -> 0.074110672 | G4: =C19/C$30 -> 0.081054688
B5: Mar | C5: 2750 | D5: Mar | E5: =C5/C$15 -> 0.074846225 | F5: =B20/B$30 -> 0.070228684 | G5: =C20/C$30 -> 0.083789062
B6: Apr | C6: 3300 | D6: Apr | E6: =C6/C$15 -> 0.08981547 | F6: =B21/B$30 -> 0.08822699 | G6: =C21/C$30 -> 0.092773438
B7: May | C7: 2700 | D7: May | E7: =C7/C$15 -> 0.073485385 | F7: =B22/B$30 -> 0.06959345 | G7: =C22/C$30 -> 0.065917969
B8: Jun | C8: 2520 | D8: Jun | E8: =C8/C$15 -> 0.068586359 | F8: =B23/B$30 -> 0.073051948 | G8: =C23/C$30 -> 0.07734375
B9: Jul | C9: 2790 | D9: Jul | E9: =C9/C$15 -> 0.075934897 | F9: =B24/B$30 -> 0.082580463 | G9: =C24/C$30 -> 0.06328125
B10: Aug | C10: 3000 | D10: Aug | E10: =C10/C$15 -> 0.081650427 | F10: =B25/B$30 -> 0.084697911 | G10: =C25/C$30 -> 0.063476562
B11: Sep | C11: 2982 | D11: Sep | E11: =C11/C$15 -> 0.081160525 | F11: =B26/B$30 -> 0.081521739 | G11: =C26/C$30 -> 0.071777344
B12: Oct | C12: 3564 | D12: Oct | E12: =C12/C$15 -> 0.097000708 | F12: =B27/B$30 -> 0.075875212 | G12: =C27/C$30 -> 0.08203125
B13: Nov | C13: 2952 | D13: Nov | E13: =C13/C$15 -> 0.08034402 | F13: =B28/B$30 -> 0.088932806 | G13: =C28/C$30 -> 0.097363281
B14: Dec | C14: 3564 | D14: Dec | E14: =C14/C$15 -> 0.097000708 | F14: =B29/B$30 -> 0.11589497 | G14: =C29/C$30 -> 0.12353516
B15: ค่า Sum | C15: =SUM(C3:C14) -> 36742 | D15: ค่า Sum | E15: =SUM(E3:E14) -> 1
B17: tea | C17: smoothie | F17: =130000000/7 -> 18571429
B18: 1350 | C18: 1000
B19: 1050 | C19: 830
B20: 995 | C20: 858
B21: 1250 | C21: 950
B22: 986 | C22: 675
B23: 1035 | C23: 792
B24: 1170 | C24: 648
B25: 1200 | C25: 650
B26: 1155 | C26: 735
B27: 1075 | C27: 840
B28: 1260 | C28: 997
B29: 1642 | C29: 1265
B30: =SUM(B18:B29) -> 14168 | C30: =SUM(C18:C29) -> 10240

Sheet Sheet1
A1: 244282 | B1: ยอดขาย(จำนวนแก้ว)
H2: ตาราง %ต่อผลรวม | L2: ยอดขายทั้งหมดในแต่ละเดือน ว่ามีความมากน้อยแค่ไหน | Q2: ผลรวมของแต่ละเดือนรวมกันตั้งแต่เดือนแรก | U2: วิเคราะห์การเปลี่ยนแปลงของแต่ละเดือน | Y2: วิเคราะห์ขาดทุนเทียบกับเดือนก่อน เป็น %
B3: month | C3: coffee | D3: tea | E3: smoothie | F3: total | H3: coffee | I3: tea | J3: smoothie | L3: coffee | M3: tea | N3: smoothie | Q3: coffee | R3: tea | S3: smoothie | U3: coffee | V3: tea | W3: smoothie | Y3: coffee | Z3: tea | AA3: smoothie | AB3: totol
B4: Jan | C4: 3700 | D4: 1350 | E4: 1000 | F4: =SUM(C4:E4) -> 6050 | H4: =C4/C$16 -> 0.10070219 | I4: =D4/D$16 -> 0.09528515 | J4: =E4/E$16 -> 0.09765625 | L4: =C4/SUM($C4:$E4) -> 0.61157025 | M4: =D4/SUM($C4:$E4) -> 0.2231405 | N4: =E4/SUM($C4:$E4) -> 0.16528926 | O4: =SUM(L4:N4) -> 1 | Q4: =C4 -> 3700 | R4: =D4 -> 1350 | S4: =E4 -> 1000 | U4: 0 | V4: 0 | W4: 0
B5: Fed | C5: 2920 | D5: 1050 | E5: 830 | F5: =SUM(C5:E5) -> 4800 | H5: =C5/C$16 -> 0.079473083 | I5: =D5/D$16 -> 0.074110672 | J5: =E5/E$16 -> 0.081054688 | L5: =C5/SUM($C5:$E5) -> 0.60833333 | M5: =D5/SUM($C5:$E5) -> 0.21875 | N5: =E5/SUM($C5:$E5) -> 0.17291667 | O5: =SUM(L5:N5) -> 1 | Q5: =Q4+C5 -> 6620 | R5: =R4+D5 -> 2400 | S5: =S4+E5 -> 1830 | U5: =C5-C4 -> -780 | V5: =D5-D4 -> -300 | W5: =E5-E4 -> -170 | Y5: =(C5-C4)/C4 -> -0.21081081 | Z5: =(D5-D4)/D4 -> -0.22222222 | AA5: =(E5-E4)/E4 -> -0.17 | AB5: =(F5-F4)/F4 -> -0.20661157
B6: Mar | C6: 2750 | D6: 995 | E6: 858 | F6: =SUM(C6:E6) -> 4603 | H6: =C6/C$16 -> 0.074846225 | I6: =D6/D$16 -> 0.070228684 | J6: =E6/E$16 -> 0.083789062 | L6: =C6/SUM($C6:$E6) -> 0.59743645 | M6: =D6/SUM($C6:$E6) -> 0.21616337 | N6: =E6/SUM($C6:$E6) -> 0.18640017 | O6: =SUM(L6:N6) -> 1 | Q6: =Q5+C6 -> 9370 | R6: =R5+D6 -> 3395 | S6: =S5+E6 -> 2688 | U6: =C6-C5 -> -170 | V6: =D6-D5 -> -55 | W6: =E6-E5 -> 28 | Y6: =(C6-C5)/C5 -> -0.058219178 | Z6: =(D6-D5)/D5 -> -0.052380952 | AA6: =(E6-E5)/E5 -> 0.03373494 | AB6: =(F6-F5)/F5 -> -0.041041667
B7: Apr | C7: 3300 | D7: 1250 | E7: 950 | F7: =SUM(C7:E7) -> 5500 | H7: =C7/C$16 -> 0.08981547 | I7: =D7/D$16 -> 0.08822699 | J7: =E7/E$16 -> 0.092773438 | L7: =C7/SUM($C7:$E7) -> 0.6 | M7: =D7/SUM($C7:$E7) -> 0.22727273 | N7: =E7/SUM($C7:$E7) -> 0.17272727 | O7: =SUM(L7:N7) -> 1 | Q7: =Q6+C7 -> 12670 | R7: =R6+D7 -> 4645 | S7: =S6+E7 -> 3638 | U7: =C7-C6 -> 550 | V7: =D7-D6 -> 255 | W7: =E7-E6 -> 92 | Y7: =(C7-C6)/C6 -> 0.2 | Z7: =(D7-D6)/D6 -> 0.25628141 | AA7: =(E7-E6)/E6 -> 0.10722611 | AB7: =(F7-F6)/F6 -> 0.19487291
B8: May | C8: 2700 | D8: 986 | E8: 675 | F8: =SUM(C8:E8) -> 4361 | H8: =C8/C$16 -> 0.073485385 | I8: =D8/D$16 -> 0.06959345 | J8: =E8/E$16 -> 0.065917969 | L8: =C8/SUM($C8:$E8) -> 0.61912405 | M8: =D8/SUM($C8:$E8) -> 0.22609493 | N8: =E8/SUM($C8:$E8) -> 0.15478101 | O8: =SUM(L8:N8) -> 1 | Q8: =Q7+C8 -> 15370 | R8: =R7+D8 -> 5631 | S8: =S7+E8 -> 4313 | U8: =C8-C7 -> -600 | V8: =D8-D7 -> -264 | W8: =E8-E7 -> -275 | Y8: =(C8-C7)/C7 -> -0.18181818 | Z8: =(D8-D7)/D7 -> -0.2112 | AA8: =(E8-E7)/E7 -> -0.28947368 | AB8: =(F8-F7)/F7 -> -0.20709091
B9: Jun | C9: 2520 | D9: 1035 | E9: 792 | F9: =SUM(C9:E9) -> 4347 | H9: =C9/C$16 -> 0.068586359 | I9: =D9/D$16 -> 0.073051948 | J9: =E9/E$16 -> 0.07734375 | L9: =C9/SUM($C9:$E9) -> 0.57971014 | M9: =D9/SUM($C9:$E9) -> 0.23809524 | N9: =E9/SUM($C9:$E9) -> 0.18219462 | O9: =SUM(L9:N9) -> 1 | Q9: =Q8+C9 -> 17890 | R9: =R8+D9 -> 6666 | S9: =S8+E9 -> 5105 | U9: =C9-C8 -> -180 | V9: =D9-D8 -> 49 | W9: =E9-E8 -> 117 | Y9: =(C9-C8)/C8 -> -0.066666667 | Z9: =(D9-D8)/D8 -> 0.04969574 | AA9: =(E9-E8)/E8 -> 0.17333333 | AB9: =(F9-F8)/F8 -> -0.0032102729
B10: Jul | C10: 2790 | D10: 1170 | E10: 648 | F10: =SUM(C10:E10) -> 4608 | H10: =C10/C$16 -> 0.075934897 | I10: =D10/D$16 -> 0.082580463 | J10: =E10/E$16 -> 0.06328125 | L10: =C10/SUM($C10:$E10) -> 0.60546875 | M10: =D10/SUM($C10:$E10) -> 0.25390625 | N10: =E10/SUM($C10:$E10) -> 0.140625 | O10: =SUM(L10:N10) -> 1 | Q10: =Q9+C10 -> 20680 | R10: =R9+D10 -> 7836 | S10: =S9+E10 -> 5753 | U10: =C10-C9 -> 270 | V10: =D10-D9 -> 135 | W10: =E10-E9 -> -144 | Y10: =(C10-C9)/C9 -> 0.10714286 | Z10: =(D10-D9)/D9 -> 0.13043478 | AA10: =(E10-E9)/E9 -> -0.18181818 | AB10: =(F10-F9)/F9 -> 0.060041408
B11: Aug | C11: 3000 | D11: 1200 | E11: 650 | F11: =SUM(C11:E11) -> 4850 | H11: =C11/C$16 -> 0.081650427 | I11: =D11/D$16 -> 0.084697911 | J11: =E11/E$16 -> 0.063476562 | L11: =C11/SUM($C11:$E11) -> 0.6185567 | M11: =D11/SUM($C11:$E11) -> 0.24742268 | N11: =E11/SUM($C11:$E11) -> 0.13402062 | O11: =SUM(L11:N11) -> 1 | Q11: =Q10+C11 -> 23680 | R11: =R10+D11 -> 9036 | S11: =S10+E11 -> 6403 | U11: =C11-C10 -> 210 | V11: =D11-D10 -> 30 | W11: =E11-E10 -> 2 | Y11: =(C11-C10)/C10 -> 0.075268817 | Z11: =(D11-D10)/D10 -> 0.025641026 | AA11: =(E11-E10)/E10 -> 0.0030864198 | AB11: =(F11-F10)/F10 -> 0.052517361
B12: Sep | C12: 2982 | D12: 1155 | E12: 735 | F12: =SUM(C12:E12) -> 4872 | H12: =C12/C$16 -> 0.081160525 | I12: =D12/D$16 -> 0.081521739 | J12: =E12/E$16 -> 0.071777344 | L12: =C12/SUM($C12:$E12) -> 0.61206897 | M12: =D12/SUM($C12:$E12) -> 0.23706897 | N12: =E12/SUM($C12:$E12) -> 0.15086207 | O12: =SUM(L12:N12) -> 1 | Q12: =Q11+C12 -> 26662 | R12: =R11+D12 -> 10191 | S12: =S11+E12 -> 7138 | U12: =C12-C11 -> -18 | V12: =D12-D11 -> -45 | W12: =E12-E11 -> 85 | Y12: =(C12-C11)/C11 -> -0.006 | Z12: =(D12-D11)/D11 -> -0.0375 | AA12: =(E12-E11)/E11 -> 0.13076923 | AB12: =(F12-F11)/F11 -> 0.0045360825
B13: Oct | C13: 3564 | D13: 1075 | E13: 840 | F13: =SUM(C13:E13) -> 5479 | H13: =C13/C$16 -> 0.097000708 | I13: =D13/D$16 -> 0.075875212 | J13: =E13/E$16 -> 0.08203125 | L13: =C13/SUM($C13:$E13) -> 0.65048366 | M13: =D13/SUM($C13:$E13) -> 0.19620369 | N13: =E13/SUM($C13:$E13) -> 0.15331265 | O13: =SUM(L13:N13) -> 1 | Q13: =Q12+C13 -> 30226 | R13: =R12+D13 -> 11266 | S13: =S12+E13 -> 7978 | U13: =C13-C12 -> 582 | V13: =D13-D12 -> -80 | W13: =E13-E12 -> 105 | Y13: =(C13-C12)/C12 -> 0.19517103 | Z13: =(D13-D12)/D12 -> -0.069264069 | AA13: =(E13-E12)/E12 -> 0.14285714 | AB13: =(F13-F12)/F12 -> 0.12458949
B14: Nov | C14: 2952 | D14: 1260 | E14: 997 | F14: =SUM(C14:E14) -> 5209 | H14: =C14/C$16 -> 0.08034402 | I14: =D14/D$16 -> 0.088932806 | J14: =E14/E$16 -> 0.097363281 | L14: =C14/SUM($C14:$E14) -> 0.56671146 | M14: =D14/SUM($C14:$E14) -> 0.24188904 | N14: =E14/SUM($C14:$E14) -> 0.1913995 | O14: =SUM(L14:N14) -> 1 | Q14: =Q13+C14 -> 33178 | R14: =R13+D14 -> 12526 | S14: =S13+E14 -> 8975 | U14: =C14-C13 -> -612 | V14: =D14-D13 -> 185 | W14: =E14-E13 -> 157 | Y14: =(C14-C13)/C13 -> -0.17171717 | Z14: =(D14-D13)/D13 -> 0.17209302 | AA14: =(E14-E13)/E13 -> 0.18690476 | AB14: =(F14-F13)/F13 -> -0.049279066
B15: Dec | C15: 3564 | D15: 1642 | E15: 1265 | F15: =SUM(C15:E15) -> 6471 | H15: =C15/C$16 -> 0.097000708 | I15: =D15/D$16 -> 0.11589497 | J15: =E15/E$16 -> 0.12353516 | L15: =C15/SUM($C15:$E15) -> 0.55076495 | M15: =D15/SUM($C15:$E15) -> 0.25374749 | N15: =E15/SUM($C15:$E15) -> 0.19548756 | O15: =SUM(L15:N15) -> 1 | Q15: =Q14+C15 -> 36742 | R15: =R14+D15 -> 14168 | S15: =S14+E15 -> 10240 | U15: =C15-C14 -> 612 | V15: =D15-D14 -> 382 | W15: =E15-E14 -> 268 | Y15: =(C15-C14)/C14 -> 0.20731707 | Z15: =(D15-D14)/D14 -> 0.3031746 | AA15: =(E15-E14)/E14 -> 0.26880642 | AB15: =(F15-F14)/F14 -> 0.24227299
B16: ค่า Sum | C16: =SUM(C4:C15) -> 36742 | D16: =SUM(D4:D15) -> 14168 | E16: =SUM(E4:E15) -> 10240 | F16: =SUM(C16:E16) -> 61150 | H16: =SUM(H4:H15) -> 1 | I16: =SUM(I4:I15) -> 1 | J16: =SUM(J4:J15) -> 1 | L16: หารหารค่า 100% ของแต่ละเดือนว่า ประเภทอะไรบ้างแบ่งเป็นกี่ % | Q16: หาผลรวมไล่ตั้งแต่เดือนแรก | U16: เทียบยอดแตกต่างกับเดือนที่แล้วเท่าไหรบ้าง | Y16: เทียบยอดกับเดือนที่แล้วว่าเป็น %
B17: ค่า average | C17: =AVERAGE(C4:C15) -> 3061.8333 | D17: =AVERAGE(D4:D15) -> 1180.6667 | E17: =AVERAGE(E4:E15) -> 853.33333 | F17: =AVERAGE(F4:F15) -> 5095.8333 | H17: หารหาค่าทำ %
B18: ค่า min | C18: =MIN(C4:C15) -> 2520 | D18: =MIN(D4:D15) -> 986 | E18: =MIN(E4:E15) -> 648 | F18: =MIN(F4:F15) -> 4347
B19: ค่า max | C19: =MAX(C4:C15) -> 3700 | D19: =MAX(D4:D15) -> 1642 | E19: =MAX(E4:E15) -> 1265 | F19: =MAX(F4:F15) -> 6471
B20: สรุป เรียนการใช้งาน Sum(+) Average(ค่าเฉลี่ย) Min Max %
F25: เพิ่มเติม กราฟ
A34: 244284 | B34: การวิเคราร์ข้อมูลทางธุรกิจเบื่องต้น | E34: ยอดขาย(จำนวนแก้ว) | G34: ลองนำข้อมูลแต่ละประเภท All SUM / 30 วัน / 12 ชม. การทำงาน / 60 นาที เพื่อไว้ใช้คำนวนพนักงาน
L35: นำไปประเมินว่ามีพนักงานพอกับลูกค่าที่เข้ามา/นาทีหรือไม่
B36: ราคา/แก้ว | C36: 59 | E36: month | F36: coffee | G36: tea | H36: smoothie | I36: รายเดือน | J36: เฉลี่ยต่อวัน | K36: เฉลี่ยต่อชั่วโมง | L36: 1แก้ว/กี่นาที | N36: รายได้/เดือน | O36: รายได้/วัน
E37: Jan | F37: 3700 | G37: 1350 | H37: 1000 | I37: =SUM(F37:H37) -> 6050 | J37: =I37/30 -> 201.66667 | K37: =J37/12 -> 16.805556 | L37: =60/K37 -> 3.5702479 | N37: =I37*$C$36 -> 356950 | O37: =N37/30 -> 11898.333
E38: Fed | F38: 2920 | G38: 1050 | H38: 830 | I38: =SUM(F38:H38) -> 4800 | J38: =I38/30 -> 160 | K38: =J38/12 -> 13.333333 | L38: =60/K38 -> 4.5 | N38: =I38*$C$36 -> 283200 | O38: =N38/30 -> 9440
E39: Mar | F39: 2750 | G39: 995 | H39: 858 | I39: =SUM(F39:H39) -> 4603 | J39: =I39/30 -> 153.43333 | K39: =J39/12 -> 12.786111 | L39: =60/K39 -> 4.6925918 | N39: =I39*$C$36 -> 271577 | O39: =N39/30 -> 9052.5667
E40: Apr | F40: 3300 | G40: 1250 | H40: 950 | I40: =SUM(F40:H40) -> 5500 | J40: =I40/30 -> 183.33333 | K40: =J40/12 -> 15.277778 | L40: =60/K40 -> 3.9272727 | N40: =I40*$C$36 -> 324500 | O40: =N40/30 -> 10816.667
E41: May | F41: 2700 | G41: 986 | H41: 675 | I41: =SUM(F41:H41) -> 4361 | J41: =I41/30 -> 145.36667 | K41: =J41/12 -> 12.113889 | L41: =60/K41 -> 4.9529924 | N41: =I41*$C$36 -> 257299 | O41: =N41/30 -> 8576.6333
E42: Jun | F42: 2520 | G42: 1035 | H42: 792 | I42: =SUM(F42:H42) -> 4347 | J42: =I42/30 -> 144.9 | K42: =J42/12 -> 12.075 | L42: =60/K42 -> 4.9689441 | N42: =I42*$C$36 -> 256473 | O42: =N42/30 -> 8549.1
E43: Jul | F43: 2790 | G43: 1170 | H43: 648 | I43: =SUM(F43:H43) -> 4608 | J43: =I43/30 -> 153.6 | K43: =J43/12 -> 12.8 | L43: =60/K43 -> 4.6875 | N43: =I43*$C$36 -> 271872 | O43: =N43/30 -> 9062.4
E44: Aug | F44: 3000 | G44: 1200 | H44: 650 | I44: =SUM(F44:H44) -> 4850 | J44: =I44/30 -> 161.66667 | K44: =J44/12 -> 13.472222 | L44: =60/K44 -> 4.4536082 | N44: =I44*$C$36 -> 286150 | O44: =N44/30 -> 9538.3333
E45: Sep | F45: 2982 | G45: 1155 | H45: 735 | I45: =SUM(F45:H45) -> 4872 | J45: =I45/30 -> 162.4 | K45: =J45/12 -> 13.533333 | L45: =60/K45 -> 4.4334975 | N45: =I45*$C$36 -> 287448 | O45: =N45/30 -> 9581.6
E46: Oct | F46: 3564 | G46: 1075 | H46: 840 | I46: =SUM(F46:H46) -> 5479 | J46: =I46/30 -> 182.63333 | K46: =J46/12 -> 15.219444 | L46: =60/K46 -> 3.9423252 | N46: =I46*$C$36 -> 323261 | O46: =N46/30 -> 10775.367
E47: Nov | F47: 2952 | G47: 1260 | H47: 997 | I47: =SUM(F47:H47) -> 5209 | J47: =I47/30 -> 173.63333 | K47: =J47/12 -> 14.469444 | L47: =60/K47 -> 4.1466692 | N47: =I47*$C$36 -> 307331 | O47: =N47/30 -> 10244.367
E48: Dec | F48: 3564 | G48: 1642 | H48: 1265 | I48: =SUM(F48:H48) -> 6471 | J48: =I48/30 -> 215.7 | K48: =J48/12 -> 17.975 | L48: =60/K48 -> 3.3379694 | N48: =I48*$C$36 -> 381789 | O48: =N48/30 -> 12726.3
I49: alt = : คลอบทับเพื่อเติมค่าผลรวม
A51: 244284 | B51: เปิดร้านกาแฟ คุ้มไหม? | D51: นำตัวอย่างการเปิดร้านกาแฟ โดยมีข้อมูลรายได้ ต่อแก้วที่ขาย ราคา รายได้เฉลี่ยนต่อวัน รายจ่ายหัดรายได้ หากำไรต่อเดือน
B53: ขายได้ | C53: 150 | D53: แก้ว/วัน | F53: หาค่ารายได้ตามจำนวนแก้ว
B54: ราคา/แก้ว | C54: 60 | D54: บาท | F54: what-if Amalysis -> Data table
...

Sheet Gen
D2: age_group | F2: Born | G2: Gen
C3: 18 | D3: =C3&" - "&C4-1 -> 18 - 25 | F3: 1923 | G3: Silent
C4: 26 | D4: =C4&" - "&C5-1 -> 26 - 30 | F4: 1946 | G4: Biby Boomer
C5: 31 | D5: =C5&" - "&C6-1 -> 31 - 40 | F5: 1965 | G5: Gen X
C6: 41 | D6: =C6&" - "&C7-1 -> 41 - 50 | F6: 1980 | G6: Gen Y
C7: 51 | D7: =C7&" - "&C8-1 -> 51 - 55 | F7: 1996 | G7: Gen Z
C8: 56 | D8: =C8&" - "&C9-1 -> 56 - 60 | F8: 2011 | G8: Gen Alpha
C9: 61 | D9: =C9&" - "&C10-1 -> 61 - 69 | F9: 2026 | G9: Undefined
C10: 70 | D10: =C10&" - "&C11-1 -> 70 - 99
C11: 100
